Workbook

Sheet README
A1: Nuclear Medicine Relational Database — Sample Project
A3: Purpose
A4: This workbook demonstrates a normalized relational database design — the kind of structure used in MS Access and SQL databases — built around a fictional Nuclear Medicine scan register.
A6: IMPORTANT — All data in this workbook is FICTIONAL.
A7: No real patient information, hospital records, or identifiable data is used anywhere in this file. All names, IDs, and dates are invented for demonstration purposes only.
A9: Database design (normalization)
A10: Instead of one big flat table, the data is split into four related tables, each holding one type of information. This avoids repeating data and mirrors how a real clinical system (e.g. Access or SQL Server) would be structured:
A11: 1. Physicians — one row per referring physician (PhysicianID is the primary key).
A12: 2. ScanTypes — one row per type of scan offered (ScanTypeID is the primary key).
A13: 3. Patients — one row per patient record (PatientID is the primary key; no identifying details, only an age band and sex for illustration).
A14: 4. Scans — one row per scan booking, linking to the other three tables via foreign keys (PatientID, ScanTypeID, PhysicianID).
A15: 5. Scan Details (Query View) — a joined view built with INDEX/MATCH formulas that pulls together data from all four tables, the way a SQL JOIN query would.
... A27: - I built a joined 'query view' using INDEX/MATCH to simulate a SQL JOIN, and I understand how the same design would translate directly into Access relationships and queries, or into basic T-SQL SELECT/JOIN statements.

Sheet Physicians
A1: PhysicianID | B1: Name | C1: Department
A2: PHY-01 | B2: Dr. Nkosi | C2: Nuclear Medicine
A3: PHY-02 | B3: Dr. van Wyk | C3: Nuclear Medicine
A4: PHY-03 | B4: Dr. Dlamini | C4: Nuclear Medicine
A5: PHY-04 | B5: Dr. Pretorius | C5: Nuclear Medicine
A6: PHY-05 | B6: Dr. Molefe | C6: Nuclear Medicine

Sheet ScanTypes
A1: ScanTypeID | B1: ScanTypeName | C1: AvgDurationMinutes
A2: ST-01 | B2: Bone Scan | C2: 45
A3: ST-02 | B3: Lung Perfusion Scan | C3: 30
A4: ST-03 | B4: Myocardial Perfusion Study | C4: 60
A5: ST-04 | B5: Thyroid Scan | C5: 20
A6: ST-05 | B6: Prostate Scan | C6: 40

Sheet Patients
A1: PatientID | B1: AgeBand | C1: Sex
A2: PAT-100 | B2: 46-60 | C2: F
A3: PAT-101 | B3: 61-75 | C3: F
A4: PAT-102 | B4: 18-30 | C4: F
A5: PAT-103 | B5: 46-60 | C5: F
A6: PAT-104 | B6: 76+ | C6: F
A7: PAT-105 | B7: 18-30 | C7: F
A8: PAT-106 | B8: 61-75 | C8: M
A9: PAT-107 | B9: 18-30 | C9: F
A10: PAT-108 | B10: 18-30 | C10: M
A11: PAT-109 | B11: 18-30 | C11: F
A12: PAT-110 | B12: 31-45 | C12: F
... A31: PAT-129 | B31: 76+ | C31: M

Sheet Scans
A1: ScanID | B1: PatientID | C1: ScanTypeID | D1: PhysicianID | E1: ScanDate | F1: Status | G1: TurnaroundDays
A2: SC-2000 | B2: PAT-116 | C2: ST-04 | D2: PHY-03 | E2: 46213 | F2: Completed | G2: 5
A3: SC-2001 | B3: PAT-102 | C3: ST-01 | D3: PHY-05 | E3: 46134 | F3: Completed | G3: 3
A4: SC-2002 | B4: PAT-104 | C4: ST-04 | D4: PHY-04 | E4: 46037 | F4: Cancelled
A5: SC-2003 | B5: PAT-102 | C5: ST-05 | D5: PHY-05 | E5: 46229 | F5: Pending
A6: SC-2004 | B6: PAT-110 | C6: ST-03 | D6: PHY-03 | E6: 46179 | F6: Completed | G6: 7
A7: SC-2005 | B7: PAT-114 | C7: ST-01 | D7: PHY-01 | E7: 46268 | F7: Completed | G7: 6
A8: SC-2006 | B8: PAT-121 | C8: ST-01 | D8: PHY-01 | E8: 46214 | F8: Completed | G8: 6
A9: SC-2007 | B9: PAT-118 | C9: ST-04 | D9: PHY-03 | E9: 46210 | F9: Completed | G9: 6
A10: SC-2008 | B10: PAT-111 | C10: ST-01 | D10: PHY-04 | E10: 46117 | F10: Completed | G10: 1
A11: SC-2009 | B11: PAT-115 | C11: ST-01 | D11: PHY-02 | E11: 46223 | F11: Completed | G11: 6
A12: SC-2010 | B12: PAT-107 | C12: ST-04 | D12: PHY-04 | E12: 46261 | F12: Pending
A13: SC-2011 | B13: PAT-102 | C13: ST-02 | D13: PHY-04 | E13: 46129 | F13: Completed | G13: 2
A14: SC-2012 | B14: PAT-126 | C14: ST-04 | D14: PHY-05 | E14: 46098 | F14: Completed | G14: 3
A15: SC-2013 | B15: PAT-121 | C15: ST-04 | D15: PHY-02 | E15: 46065 | F15: Completed | G15: 2
A16: SC-2014 | B16: PAT-107 | C16: ST-02 | D16: PHY-01 | E16: 46151 | F16: Pending
A17: SC-2015 | B17: PAT-105 | C17: ST-03 | D17: PHY-03 | E17: 46028 | F17: Completed | G17: 5
A18: SC-2016 | B18: PAT-111 | C18: ST-05 | D18: PHY-05 | E18: 46108 | F18: Cancelled
A19: SC-2017 | B19: PAT-122 | C19: ST-05 | D19: PHY-05 | E19: 46194 | F19: Completed | G19: 1
A20: SC-2018 | B20: PAT-114 | C20: ST-05 | D20: PHY-04 | E20: 46128 | F20: Completed | G20: 1
A21: SC-2019 | B21: PAT-115 | C21: ST-04 | D21: PHY-01 | E21: 46075 | F21: Completed | G21: 2
A22: SC-2020 | B22: PAT-114 | C22: ST-02 | D22: PHY-01 | E22: 46114 | F22: Completed | G22: 1
A23: SC-2021 | B23: PAT-100 | C23: ST-05 | D23: PHY-02 | E23: 46164 | F23: Completed | G23: 3
A24: SC-2022 | B24: PAT-119 | C24: ST-01 | D24: PHY-01 | E24: 46250 | F24: Completed | G24: 4
A25: SC-2023 | B25: PAT-104 | C25: ST-03 | D25: PHY-03 | E25: 46181 | F25: Completed | G25: 1
A26: SC-2024 | B26: PAT-103 | C26: ST-04 | D26: PHY-04 | E26: 46149 | F26: Completed | G26: 1
A27: SC-2025 | B27: PAT-104 | C27: ST-01 | D27: PHY-03 | E27: 46216 | F27: Completed | G27: 7
A28: SC-2026 | B28: PAT-122 | C28: ST-02 | D28: PHY-05 | E28: 46032 | F28: Completed | G28: 5
A29: SC-2027 | B29: PAT-111 | C29: ST-02 | D29: PHY-05 | E29: 46261 | F29: Completed | G29: 5
A30: SC-2028 | B30: PAT-109 | C30: ST-01 | D30: PHY-03 | E30: 46159 | F30: Completed | G30: 2
A31: SC-2029 | B31: PAT-111 | C31: ST-02 | D31: PHY-05 | E31: 46165 | F31: Pending
A32: SC-2030 | B32: PAT-110 | C32: ST-02 | D32: PHY-05 | E32: 46234 | F32: Pending
A33: SC-2031 | B33: PAT-124 | C33: ST-02 | D33: PHY-02 | E33: 46236 | F33: Completed | G33: 7
A34: SC-2032 | B34: PAT-107 | C34: ST-02 | D34: PHY-05 | E34: 46153 | F34: Completed | G34: 1
A35: SC-2033 | B35: PAT-100 | C35: ST-03 | D35: PHY-04 | E35: 46093 | F35: Completed | G35: 5
A36: SC-2034 | B36: PAT-111 | C36: ST-04 | D36: PHY-03 | E36: 46271 | F36: Cancelled
A37: SC-2035 | B37: PAT-102 | C37: ST-02 | D37: PHY-01 | E37: 46085 | F37: Completed | G37: 3
A38: SC-2036 | B38: PAT-106 | C38: ST-04 | D38: PHY-05 | E38: 46257 | F38: Completed | G38: 1
A39: SC-2037 | B39: PAT-115 | C39: ST-03 | D39: PHY-01 | E39: 46240 | F39: Completed | G39: 4
A40: SC-2038 | B40: PAT-125 | C40: ST-02 | D40: PHY-04 | E40: 46254 | F40: Completed | G40: 7
...

Sheet Scan Details (Query View)
A1: ScanID | B1: ScanDate | C1: Scan Type | D1: Referring Physician | E1: Patient Age Band | F1: Patient Sex | G1: Status | H1: Turnaround (days)
A2: =Scans!A2 -> SC-2000 | B2: =Scans!E2 -> 46213 | C2: =INDEX(ScanTypes!$B$2:$B$6,MATCH(Scans!C2,ScanTypes!$A$2:$A$6,0)) -> Thyroid Scan | D2: =INDEX(Physicians!$B$2:$B$6,MATCH(Scans!D2,Physicians!$A$2:$A$6,0)) -> Dr. Dlamini | E2: =INDEX(Patients!$B$2:$B$31,MATCH(Scans!B2,Patients!$A$2:$A$31,0)) -> 76+ | F2: =INDEX(Patients!$C$2:$C$31,MATCH(Scans!B2,Patients!$A$2:$A$31,0)) -> M | G2: =Scans!F2 -> Completed | H2: =IF(Scans!G2="","",Scans!G2) -> 5
A3: =Scans!A3 -> SC-2001 | B3: =Scans!E3 -> 46134 | C3: =INDEX(ScanTypes!$B$2:$B$6,MATCH(Scans!C3,ScanTypes!$A$2:$A$6,0)) -> Bone Scan | D3: =INDEX(Physicians!$B$2:$B$6,MATCH(Scans!D3,Physicians!$A$2:$A$6,0)) -> Dr. Molefe | E3: =INDEX(Patients!$B$2:$B$31,MATCH(Scans!B3,Patients!$A$2:$A$31,0)) -> 18-30 | F3: =INDEX(Patients!$C$2:$C$31,MATCH(Scans!B3,Patients!$A$2:$A$31,0)) -> F | G3: =Scans!F3 -> Completed | H3: =IF(Scans!G3="","",Scans!G3) -> 3
A4: =Scans!A4 -> SC-2002 | B4: =Scans!E4 -> 46037 | C4: =INDEX(ScanTypes!$B$2:$B$6,MATCH(Scans!C4,ScanTypes!$A$2:$A$6,0)) -> Thyroid Scan | D4: =INDEX(Physicians!$B$2:$B$6,MATCH(Scans!D4,Physicians!$A$2:$A$6,0)) -> Dr. Pretorius | E4: =INDEX(Patients!$B$2:$B$31,MATCH(Scans!B4,Patients!$A$2:$A$31,0)) -> 76+ | F4: =INDEX(Patients!$C$2:$C$31,MATCH(Scans!B4,Patients!$A$2:$A$31,0)) -> F | G4: =Scans!F4 -> Cancelled | H4: =IF(Scans!G4="","",Scans!G4)
A5: =Scans!A5 -> SC-2003 | B5: =Scans!E5 -> 46229 | C5: =INDEX(ScanTypes!$B$2:$B$6,MATCH(Scans!C5,ScanTypes!$A$2:$A$6,0)) -> Prostate Scan | D5: =INDEX(Physicians!$B$2:$B$6,MATCH(Scans!D5,Physicians!$A$2:$A$6,0)) -> Dr. Molefe | E5: =INDEX(Patients!$B$2:$B$31,MATCH(Scans!B5,Patients!$A$2:$A$31,0)) -> 18-30 | F5: =INDEX(Patients!$C$2:$C$31,MATCH(Scans!B5,Patients!$A$2:$A$31,0)) -> F | G5: =Scans!F5 -> Pending | H5: =IF(Scans!G5="","",Scans!G5)
A6: =Scans!A6 -> SC-2004 | B6: =Scans!E6 -> 46179 | C6: =INDEX(ScanTypes!$B$2:$B$6,MATCH(Scans!C6,ScanTypes!$A$2:$A$6,0)) -> Myocardial Perfusion Study | D6: =INDEX(Physicians!$B$2:$B$6,MATCH(Scans!D6,Physicians!$A$2:$A$6,0)) -> Dr. Dlamini | E6: =INDEX(Patients!$B$2:$B$31,MATCH(Scans!B6,Patients!$A$2:$A$31,0)) -> 31-45 | F6: =INDEX(Patients!$C$2:$C$31,MATCH(Scans!B6,Patients!$A$2:$A$31,0)) -> F | G6: =Scans!F6 -> Completed | H6: =IF(Scans!G6="","",Scans!G6) -> 7
A7: =Scans!A7 -> SC-2005 | B7: =Scans!E7 -> 46268 | C7: =INDEX(ScanTypes!$B$2:$B$6,MATCH(Scans!C7,ScanTypes!$A$2:$A$6,0)) -> Bone Scan | D7: =INDEX(Physicians!$B$2:$B$6,MATCH(Scans!D7,Physicians!$A$2:$A$6,0)) -> Dr. Nkosi | E7: =INDEX(Patients!$B$2:$B$31,MATCH(Scans!B7,Patients!$A$2:$A$31,0)) -> 46-60 | F7: =INDEX(Patients!$C$2:$C$31,MATCH(Scans!B7,Patients!$A$2:$A$31,0)) -> M | G7: =Scans!F7 -> Completed | H7: =IF(Scans!G7="","",Scans!G7) -> 6
A8: =Scans!A8 -> SC-2006 | B8: =Scans!E8 -> 46214 | C8: =INDEX(ScanTypes!$B$2:$B$6,MATCH(Scans!C8,ScanTypes!$A$2:$A$6,0)) -> Bone Scan | D8: =INDEX(Physicians!$B$2:$B$6,MATCH(Scans!D8,Physicians!$A$2:$A$6,0)) -> Dr. Nkosi | E8: =INDEX(Patients!$B$2:$B$31,MATCH(Scans!B8,Patients!$A$2:$A$31,0)) -> 76+ | F8: =INDEX(Patients!$C$2:$C$31,MATCH(Scans!B8,Patients!$A$2:$A$31,0)) -> F | G8: =Scans!F8 -> Completed | H8: =IF(Scans!G8="","",Scans!G8) -> 6
A9: =Scans!A9 -> SC-2007 | B9: =Scans!E9 -> 46210 | C9: =INDEX(ScanTypes!$B$2:$B$6,MATCH(Scans!C9,ScanTypes!$A$2:$A$6,0)) -> Thyroid Scan | D9: =INDEX(Physicians!$B$2:$B$6,MATCH(Scans!D9,Physicians!$A$2:$A$6,0)) -> Dr. Dlamini | E9: =INDEX(Patients!$B$2:$B$31,MATCH(Scans!B9,Patients!$A$2:$A$31,0)) -> 18-30 | F9: =INDEX(Patients!$C$2:$C$31,MATCH(Scans!B9,Patients!$A$2:$A$31,0)) -> F | G9: =Scans!F9 -> Completed | H9: =IF(Scans!G9="","",Scans!G9) -> 6
A10: =Scans!A10 -> SC-2008 | B10: =Scans!E10 -> 46117 | C10: =INDEX(ScanTypes!$B$2:$B$6,MATCH(Scans!C10,ScanTypes!$A$2:$A$6,0)) -> Bone Scan | D10: =INDEX(Physicians!$B$2:$B$6,MATCH(Scans!D10,Physicians!$A$2:$A$6,0)) -> Dr. Pretorius | E10: =INDEX(Patients!$B$2:$B$31,MATCH(Scans!B10,Patients!$A$2:$A$31,0)) -> 76+ | F10: =INDEX(Patients!$C$2:$C$31,MATCH(Scans!B10,Patients!$A$2:$A$31,0)) -> M | G10: =Scans!F10 -> Completed | H10: =IF(Scans!G10="","",Scans!G10) -> 1
A11: =Scans!A11 -> SC-2009 | B11: =Scans!E11 -> 46223 | C11: =INDEX(ScanTypes!$B$2:$B$6,MATCH(Scans!C11,ScanTypes!$A$2:$A$6,0)) -> Bone Scan | D11: =INDEX(Physicians!$B$2:$B$6,MATCH(Scans!D11,Physicians!$A$2:$A$6,0)) -> Dr. van Wyk | E11: =INDEX(Patients!$B$2:$B$31,MATCH(Scans!B11,Patients!$A$2:$A$31,0)) -> 31-45 | F11: =INDEX(Patients!$C$2:$C$31,MATCH(Scans!B11,Patients!$A$2:$A$31,0)) -> F | G11: =Scans!F11 -> Completed | H11: =IF(Scans!G11="","",Scans!G11) -> 6
A12: =Scans!A12 -> SC-2010 | B12: =Scans!E12 -> 46261 | C12: =INDEX(ScanTypes!$B$2:$B$6,MATCH(Scans!C12,ScanTypes!$A$2:$A$6,0)) -> Thyroid Scan | D12: =INDEX(Physicians!$B$2:$B$6,MATCH(Scans!D12,Physicians!$A$2:$A$6,0)) -> Dr. Pretorius | E12: =INDEX(Patients!$B$2:$B$31,MATCH(Scans!B12,Patients!$A$2:$A$31,0)) -> 18-30 | F12: =INDEX(Patients!$C$2:$C$31,MATCH(Scans!B12,Patients!$A$2:$A$31,0)) -> F | G12: =Scans!F12 -> Pending | H12: =IF(Scans!G12="","",Scans!G12)
A13: =Scans!A13 -> SC-2011 | B13: =Scans!E13 -> 46129 | C13: =INDEX(ScanTypes!$B$2:$B$6,MATCH(Scans!C13,ScanTypes!$A$2:$A$6,0)) -> Lung Perfusion Scan | D13: =INDEX(Physicians!$B$2:$B$6,MATCH(Scans!D13,Physicians!$A$2:$A$6,0)) -> Dr. Pretorius | E13: =INDEX(Patients!$B$2:$B$31,MATCH(Scans!B13,Patients!$A$2:$A$31,0)) -> 18-30 | F13: =INDEX(Patients!$C$2:$C$31,MATCH(Scans!B13,Patients!$A$2:$A$31,0)) -> F | G13: =Scans!F13 -> Completed | H13: =IF(Scans!G13="","",Scans!G13) -> 2
... A71: =Scans!A71 -> SC-2069 | B71: =Scans!E71 -> 46094 | C71: =INDEX(ScanTypes!$B$2:$B$6,MATCH(Scans!C71,ScanTypes!$A$2:$A$6,0)) -> Bone Scan | D71: =INDEX(Physicians!$B$2:$B$6,MATCH(Scans!D71,Physicians!$A$2:$A$6,0)) -> Dr. Nkosi | E71: =INDEX(Patients!$B$2:$B$31,MATCH(Scans!B71,Patients!$A$2:$A$31,0)) -> 31-45 | F71: =INDEX(Patients!$C$2:$C$31,MATCH(Scans!B71,Patients!$A$2:$A$31,0)) -> F | G71: =Scans!F71 -> Completed | H71: =IF(Scans!G71="","",Scans!G71) -> 7

Sheet Query Examples
A1: Completed Scans by Scan Type
A2: Scan Type | B2: Completed Count
A3: Bone Scan | B3: =COUNTIFS('Scan Details (Query View)'!$C$2:$C$71,A3,'Scan Details (Query View)'!$G$2:$G$71,"Completed") -> 17
A4: Lung Perfusion Scan | B4: =COUNTIFS('Scan Details (Query View)'!$C$2:$C$71,A4,'Scan Details (Query View)'!$G$2:$G$71,"Completed") -> 15
A5: Myocardial Perfusion Study | B5: =COUNTIFS('Scan Details (Query View)'!$C$2:$C$71,A5,'Scan Details (Query View)'!$G$2:$G$71,"Completed") -> 8
A6: Thyroid Scan | B6: =COUNTIFS('Scan Details (Query View)'!$C$2:$C$71,A6,'Scan Details (Query View)'!$G$2:$G$71,"Completed") -> 11
A7: Prostate Scan | B7: =COUNTIFS('Scan Details (Query View)'!$C$2:$C$71,A7,'Scan Details (Query View)'!$G$2:$G$71,"Completed") -> 5
A9: Scan Volume by Patient Age Band
A10: Age Band | B10: Count
A11: 18-30 | B11: =COUNTIFS('Scan Details (Query View)'!$E$2:$E$71,A11) -> 14
A12: 31-45 | B12: =COUNTIFS('Scan Details (Query View)'!$E$2:$E$71,A12) -> 13
A13: 46-60 | B13: =COUNTIFS('Scan Details (Query View)'!$E$2:$E$71,A13) -> 15
A14: 61-75 | B14: =COUNTIFS('Scan Details (Query View)'!$E$2:$E$71,A14) -> 5
A15: 76+ | B15: =COUNTIFS('Scan Details (Query View)'!$E$2:$E$71,A15) -> 23
